Workbook

Sheet Données financières brutes
A1: Société | B1: Cap. Propores (MD) | D1: CA (MD) | F1: Résultat Net (MD) | H1: Total Bilan (MD) | J1: Immob. Fin. (MD) | L1: Ch. Personnel | N1: Ch. Exploit. | P1: Rés. Exploit. | R1: Prod. Placement
B2: 2025 | C2: 2024 | D2: 2025 | E2: 2024 | F2: 2025 | G2: 2024 | H2: 2025 | I2: 2024 | J2: 2025 | K2: 2024 | L2: 2025 | M2: 2024 | N2: 2025 | O2: 2024 | P2: 2025 | Q2: 2024 | R2: 2025 | S2: 2024
A3: Amen Invest | B3: 5.558 | C3: 4.317 | D3: 3.489 | E3: 2.51 | F3: 1.24 | G3: 0.56 | H3: 19.374 | I3: 11.813 | J3: 2.373 | K3: 1.911 | L3: 1.627 | M3: 1.279 | N3: 2.263 | O3: 2.112 | P3: 1.226 | Q3: 0.398 | R3: 0.292 | S3: 0.272
A4: AFC | B4: 4.685 | C4: 3.802 | D4: 5.209 | E4: 4.032 | F4: 0.879 | G4: 0.434 | H4: 22.689 | I4: 8.33 | J4: 1.548 | K4: 1.175 | L4: 3.443 | M4: 2.793 | N4: 4.623 | O4: 4.016 | P4: 0.585 | Q4: 0.015 | R4: 0.418 | S4: 0.307
A5: Attijari Intermed. | B5: 5.956 | C5: 6.263 | D5: 1.263 | E5: 2.957 | F5: -0.177 | G5: 0.32 | H5: 25.137 | I5: 23.597 | J5: 1.542 | K5: 1.477 | L5: 1.495 | M5: 1.5 | N5: 1.993 | O5: 2.981 | P5: -0.729 | Q5: 0.024 | R5: 0.535 | S5: 0.297
A6: BH Invest | B6: 10.553 | C6: 10.509 | D6: 2.727 | E6: 5.793 | F6: 0.541 | G6: 2.26 | H6: 26.875 | I6: 18.48 | J6: 5.971 | K6: 4.935 | L6: 2.155 | M6: 2.008 | N6: 3.255 | O6: 3.455 | P6: -0.527 | Q6: 2.338 | R6: 1.141 | S6: 0.516
A7: BMCE | B7: 1.991 | C7: 2.309 | D7: 1.275 | E7: 1.198 | F7: -0.318 | G7: 0.176 | H7: 36.711 | I7: 6.614 | J7: 1.195 | K7: 1.129 | L7: 0.667 | M7: 0.537 | N7: 1.556 | O7: 1.219 | P7: -0.28 | Q7: -0.02 | R7: N/D | S7: N/D
A8: BNA Capitaux | B8: 21.151 | C8: 24.228 | D8: 5.831 | E8: 12.2 | F8: 2.073 | G8: 6.877 | H8: 30.169 | I8: 30.044 | J8: 2.138 | K8: 2.034 | L8: 4.559 | M8: 3.826 | N8: 5.543 | O8: 5.037 | P8: 0.288 | Q8: 7.162 | R8: 2.298 | S8: 1.762
A9: BTK Conseil | B9: 2.393 | C9: 1.906 | D9: 1.68 | E9: 1.428 | F9: 0.487 | G9: 0.542 | H9: 5.62 | I9: 4.188 | J9: 0.973 | K9: 0.907 | L9: 0.693 | M9: 0.593 | N9: 0.978 | O9: 0.806 | P9: 0.701 | Q9: 0.622 | R9: N/D | S9: N/D
A10: CGI | B10: 1.781 | C10: 1.695 | D10: 0.482 | E10: 0.461 | F10: 0.086 | G10: 0.138 | H10: 5.2 | I10: 2.965 | J10: 0.989 | K10: 0.915 | L10: 0.345 | M10: 0.253 | N10: 0.546 | O10: 0.439 | P10: -0.063 | Q10: 0.021 | R10: 0.214 | S10: 0.154
A11: FINACORP | B11: 1.183 | C11: 2.154 | D11: 0.367 | E11: 0.832 | F11: -0.971 | G11: -0.029 | H11: 5.752 | I11: 6.848 | J11: 1.022 | K11: 0.963 | L11: 0.813 | M11: 0.736 | N11: 1.402 | O11: 1.32 | P11: -1.035 | Q11: -0.487 | R11: 0.033 | S11: 0.447
A12: MAC SA | B12: 20.735 | C12: 14.714 | D12: 29.51 | E12: 18.94 | F12: 7.07 | G12: 2.591 | H12: 55.798 | I12: 67.076 | J12: 4.703 | K12: 4.463 | L12: 6.293 | M12: 5.877 | N12: 20.051 | O12: 16.687 | P12: 9.459 | Q12: 2.253 | R12: 1.058 | S12: 1.799
A13: MAXULA | B13: 5.734 | C13: 5.526 | D13: 2.767 | E13: 2.02 | F13: 0.207 | G13: -0.268 | H13: 11.535 | I13: 11.329 | J13: 4.491 | K13: 4.818 | L13: 1.183 | M13: 1.035 | N13: 2.544 | O13: 2.196 | P13: 0.222 | Q13: -0.176 | R13: 0.296 | S13: 0.202
A14: MCP | B14: 2.684 | C14: 2.801 | D14: 0.988 | E14: 0.981 | F14: -0.177 | G14: 0.211 | H14: 7.91 | I14: 7.689 | J14: 1.241 | K14: 1.12 | L14: 0.813 | M14: 0.736 | N14: 1.309 | O14: 1.331 | P14: 0.32 | Q14: -0.35 | R14: 0.112 | S14: 0.525
A15: SBT | B15: 3.597 | C15: 2.244 | D15: 2.099 | E15: 1.308 | F15: 0.852 | G15: 0.347 | H15: 4.181 | I15: 2.594 | J15: 0.983 | K15: 0.918 | L15: 0.749 | M15: 0.731 | N15: 1.177 | O15: 0.992 | P15: 0.922 | Q15: 0.316 | R15: 0.154 | S15: 0.102
A16: STB Finance | B16: 15.852 | C16: 17.135 | D16: 2.709 | E16: 11.73 | F16: 0.264 | G16: 4.329 | H16: 30.505 | I16: 29.927 | J16: 6.228 | K16: 5.07 | L16: 2.9 | M16: 2.866 | N16: 3.394 | O16: 7.006 | P16: -0.648 | Q16: 4.724 | R16: 1.067 | S16: 0.923
A17: Tunisie Valeurs | B17: 52.821 | C17: 49.043 | D17: 21.373 | E17: 19.62 | F17: 3.928 | G17: 5.353 | H17: 118.569 | I17: 109.717 | J17: 15.204 | K17: 14.641 | L17: 14.999 | M17: 12.406 | N17: 25.409 | O17: 21.444 | P17: -4.036 | Q17: -1.824 | R17: 11.355 | S17: 8.344
A18: UFI | B18: 27.168 | C18: 27.328 | D18: 4.655 | E18: 5.033 | F18: 4.839 | G18: 5.007 | H18: 30.449 | I18: 30.153 | J18: 2.789 | K18: 2.739 | L18: 1.106 | M18: 0.957 | N18: 2.299 | O18: 2.049 | P18: 2.356 | Q18: 2.983 | R18: 5.759 | S18: 4.939
A19: UIB Finance | B19: 3.258 | C19: 2.954 | D19: 1.153 | E19: 0.963 | F19: 0.304 | G19: 0.338 | H19: 5.618 | I19: 5.621 | J19: 0.978 | K19: 0.914 | L19: 0.805 | M19: 0.663 | N19: 0.924 | O19: 0.838 | P19: 0.228 | Q19: 0.124 | R19: 0.138 | S19: 0.25
A20: Union Capital | B20: 10.587 | C20: 8.703 | D20: 2.95 | E20: 1.561 | F20: 1.884 | G20: 1.209 | H20: 13.187 | I20: 10.889 | J20: 1.038 | K20: 0.993 | L20: 0.72 | M20: 0.576 | N20: 1.15 | O20: 1.147 | P20: 1.8 | Q20: 0.414 | R20: 0.439 | S20: 0.916
A21: Total | B21: =SUM(B3:B20) -> 197.687 | C21: =SUM(C3:C20) -> 187.631 | D21: =SUM(D3:D20) -> 90.527 | E21: =SUM(E3:E20) -> 93.567 | F21: =SUM(F3:F20) -> 23.011 | G21: =SUM(G3:G20) -> 30.395 | H21: =SUM(H3:H20) -> 455.279 | I21: =SUM(I3:I20) -> 387.874 | ... S21: =SUM(S3:S20) -> 21.755

Sheet Données financières 2025
A1: Société | B1: Cap. Propores (MD) | C1: CA (MD) | D1: Résultat Net (MD) | E1: Total Bilan (MD) | F1: Immob. Fin. (MD) | G1: Ch. Personnel | H1: Ch. Exploit. | I1: Rés. Exploit. | J1: Prod. Placement
A2: Amen Invest | B2: 5.558 | C2: 3.489 | D2: 1.24 | E2: 19.374 | F2: 2.373 | G2: 1.627 | H2: 2.263 | I2: 1.226 | J2: 0.292
A3: AFC | B3: 4.685 | C3: 5.209 | D3: 0.879 | E3: 22.689 | F3: 1.548 | G3: 3.443 | H3: 4.623 | I3: 0.585 | J3: 0.418
A4: Attijari Intermed. | B4: 5.956 | C4: 1.263 | D4: -0.177 | E4: 25.137 | F4: 1.542 | G4: 1.495 | H4: 1.993 | I4: -0.729 | J4: 0.535
A5: BH Invest | B5: 10.553 | C5: 2.727 | D5: 0.541 | E5: 26.875 | F5: 5.971 | G5: 2.155 | H5: 3.255 | I5: -0.527 | J5: 1.141
A6: BMCE | B6: 1.991 | C6: 1.275 | D6: -0.318 | E6: 36.711 | F6: 1.195 | G6: 0.667 | H6: 1.556 | I6: -0.28 | J6: N/D
A7: BNA Capitaux | B7: 21.151 | C7: 5.831 | D7: 2.073 | E7: 30.169 | F7: 2.138 | G7: 4.559 | H7: 5.543 | I7: 0.288 | J7: 2.298
A8: BTK Conseil | B8: 2.393 | C8: 1.68 | D8: 0.487 | E8: 5.62 | F8: 0.973 | G8: 0.693 | H8: 0.978 | I8: 0.701 | J8: N/D
A9: CGI | B9: 1.781 | C9: 0.482 | D9: 0.086 | E9: 5.2 | F9: 0.989 | G9: 0.345 | H9: 0.546 | I9: -0.063 | J9: 0.214
A10: FINACORP | B10: 1.183 | C10: 0.367 | D10: -0.971 | E10: 5.752 | F10: 1.022 | G10: 0.813 | H10: 1.402 | I10: -1.035 | J10: 0.033
A11: MAC SA | B11: 20.735 | C11: 29.51 | D11: 7.07 | E11: 55.798 | F11: 4.703 | G11: 6.293 | H11: 20.051 | I11: 9.459 | J11: 1.058
A12: MAXULA | B12: 5.734 | C12: 2.767 | D12: 0.207 | E12: 11.535 | F12: 4.491 | G12: 1.183 | H12: 2.544 | I12: 0.222 | J12: 0.296
A13: MCP | B13: 2.684 | C13: 0.988 | D13: -0.177 | E13: 7.91 | F13: 1.241 | G13: 0.813 | H13: 1.309 | I13: 0.32 | J13: 0.112
A14: SBT | B14: 3.597 | C14: 2.099 | D14: 0.852 | E14: 4.181 | F14: 0.983 | G14: 0.749 | H14: 1.177 | I14: 0.922 | J14: 0.154
A15: STB Finance | B15: 15.852 | C15: 2.709 | D15: 0.264 | E15: 30.505 | F15: 6.228 | G15: 2.9 | H15: 3.394 | I15: -0.648 | J15: 1.067
A16: Tunisie Valeurs | B16: 52.821 | C16: 21.373 | D16: 3.928 | E16: 118.569 | F16: 15.204 | G16: 14.999 | H16: 25.409 | I16: -4.036 | J16: 11.355
A17: UFI | B17: 27.168 | C17: 4.655 | D17: 4.839 | E17: 30.449 | F17: 2.789 | G17: 1.106 | H17: 2.299 | I17: 2.356 | J17: 5.759
A18: UIB Finance | B18: 3.258 | C18: 1.153 | D18: 0.304 | E18: 5.618 | F18: 0.978 | G18: 0.805 | H18: 0.924 | I18: 0.228 | J18: 0.138
A19: Union Capital | B19: 10.587 | C19: 2.95 | D19: 1.884 | E19: 13.187 | F19: 1.038 | G19: 0.72 | H19: 1.15 | I19: 1.8 | J19: 0.439
A20: Total | B20: =SUM(B2:B19) -> 197.687 | C20: =SUM(C2:C19) -> 90.527 | D20: =SUM(D2:D19) -> 23.011 | E20: =SUM(E2:E19) -> 455.279 | F20: =SUM(F2:F19) -> 55.406 | G20: =SUM(G2:G19) -> 45.365 | H20: =SUM(H2:H19) -> 80.416 | I20: =SUM(I2:I19) -> 10.789 | J20: =SUM(J2:J19) -> 25.309

Sheet CA
A1: Société | B1: CA
B2: 2025 | C2: 2024
A3: Amen Invest | B3: 3.489 | C3: 2.51
A4: AFC | B4: 5.209 | C4: 4.032
A5: Attijari Intermed. | B5: 1.263 | C5: 2.957
A6: BH Invest | B6: 2.727 | C6: 5.793
A7: BMCE | B7: 1.275 | C7: 1.198
A8: BNA Capitaux | B8: 5.831 | C8: 12.2
A9: BTK Conseil | B9: 1.68 | C9: 1.428
A10: CGI | B10: 0.482 | C10: 0.461
A11: FINACORP | B11: 0.367 | C11: 0.832
A12: MAC SA | B12: 29.51 | C12: 18.94
A13: MAXULA | B13: 2.767 | C13: 2.02
A14: MCP | B14: 0.988 | C14: 0.981
... A20: Union Capital | B20: 2.95 | C20: 1.561
A21: Total | B21: =SUM(B3:B20) -> 90.527 | C21: =SUM(C3:C20) -> 93.567

Sheet ROE
A1: Société | B1: ROE (%) | D1: vs Moyenne
B2: 2025 | C2: 2024 | D2: 2025 | E2: 2024
A3: Amen Invest | B3: ='Données financières brutes'!F3/'Données financières brutes'!B3 -> 0.22310184 | C3: ='Données financières brutes'!G3/'Données financières brutes'!C3 -> 0.12971971 | D3: =B3-B$21 -> 0.10670066 | E3: =C3-C$21 -> -0.032273774
A4: AFC | B4: ='Données financières brutes'!F4/'Données financières brutes'!B4 -> 0.18762006 | C4: ='Données financières brutes'!G4/'Données financières brutes'!C4 -> 0.11415045 | D4: =B4-B$21 -> 0.071218884 | E4: =C4-C$21 -> -0.04784304
A5: Attijari Intermed. | B5: ='Données financières brutes'!F5/'Données financières brutes'!B5 -> -0.029717931 | C5: ='Données financières brutes'!G5/'Données financières brutes'!C5 -> 0.051093725 | D5: =B5-B$21 -> -0.14611911 | E5: =C5-C$21 -> -0.11089976
A6: BH Invest | B6: ='Données financières brutes'!F6/'Données financières brutes'!B6 -> 0.051265043 | C6: ='Données financières brutes'!G6/'Données financières brutes'!C6 -> 0.21505376 | D6: =B6-B$21 -> -0.065136137 | E6: =C6-C$21 -> 0.053060276
A7: BMCE | B7: ='Données financières brutes'!F7/'Données financières brutes'!B7 -> -0.15971873 | C7: ='Données financières brutes'!G7/'Données financières brutes'!C7 -> 0.076223473 | D7: =B7-B$21 -> -0.27611991 | E7: =C7-C$21 -> -0.085770014
A8: BNA Capitaux | B8: ='Données financières brutes'!F8/'Données financières brutes'!B8 -> 0.09800955 | C8: ='Données financières brutes'!G8/'Données financières brutes'!C8 -> 0.28384514 | D8: =B8-B$21 -> -0.018391629 | E8: =C8-C$21 -> 0.12185165
A9: BTK Conseil | B9: ='Données financières brutes'!F9/'Données financières brutes'!B9 -> 0.20351024 | C9: ='Données financières brutes'!G9/'Données financières brutes'!C9 -> 0.28436516 | D9: =B9-B$21 -> 0.087109059 | E9: =C9-C$21 -> 0.12237168
A10: CGI | B10: ='Données financières brutes'!F10/'Données financières brutes'!B10 -> 0.048287479 | C10: ='Données financières brutes'!G10/'Données financières brutes'!C10 -> 0.081415929 | D10: =B10-B$21 -> -0.068113701 | E10: =C10-C$21 -> -0.080577558
A11: FINACORP | B11: ='Données financières brutes'!F11/'Données financières brutes'!B11 -> -0.82079459 | C11: ='Données financières brutes'!G11/'Données financières brutes'!C11 -> -0.013463324 | D11: =B11-B$21 -> -0.93719577 | E11: =C11-C$21 -> -0.17545681
A12: MAC SA | B12: ='Données financières brutes'!F12/'Données financières brutes'!B12 -> 0.34096938 | C12: ='Données financières brutes'!G12/'Données financières brutes'!C12 -> 0.1760908 | D12: =B12-B$21 -> 0.2245682 | E12: =C12-C$21 -> 0.014097311
A13: MAXULA | B13: ='Données financières brutes'!F13/'Données financières brutes'!B13 -> 0.036100453 | C13: ='Données financières brutes'!G13/'Données financières brutes'!C13 -> -0.048498009 | D13: =B13-B$21 -> -0.080300726 | E13: =C13-C$21 -> -0.2104915
A14: MCP | B14: ='Données financières brutes'!F14/'Données financières brutes'!B14 -> -0.065946349 | C14: ='Données financières brutes'!G14/'Données financières brutes'!C14 -> 0.075330239 | D14: =B14-B$21 -> -0.18234753 | E14: =C14-C$21 -> -0.086663248
... A20: Union Capital | B20: ='Données financières brutes'!F20/'Données financières brutes'!B20 -> 0.17795409 | C20: ='Données financières brutes'!G20/'Données financières brutes'!C20 -> 0.13891761 | D20: =B20-B$21 -> 0.061552915 | E20: =C20-C$21 -> -0.023075873
A21: Moyenne | B21: ='Données financières brutes'!F21/'Données financières brutes'!B21 -> 0.11640118 | C21: ='Données financières brutes'!G21/'Données financières brutes'!C21 -> 0.16199349

Sheet Ch. Personnel
A1: Société | B1: Ratio Ch. Personnel (%) | D1: vs Moyenne
B2: 2025 | C2: 2024 | D2: 2025 | E2: 2024
A3: Amen Invest | B3: ='Données financières brutes'!L3/'Données financières brutes'!D3 -> 0.46632273 | C3: ='Données financières brutes'!M3/'Données financières brutes'!E3 -> 0.50956175 | D3: =B3-B$21 -> -0.034798484 | E3: =C3-C$21 -> 0.088772372
A4: AFC | B4: ='Données financières brutes'!L4/'Données financières brutes'!D4 -> 0.6609714 | C4: ='Données financières brutes'!M4/'Données financières brutes'!E4 -> 0.69270833 | D4: =B4-B$21 -> 0.15985018 | E4: =C4-C$21 -> 0.27191895
A5: Attijari Intermed. | B5: ='Données financières brutes'!L5/'Données financières brutes'!D5 -> 1.1836896 | C5: ='Données financières brutes'!M5/'Données financières brutes'!E5 -> 0.50727088 | D5: =B5-B$21 -> 0.68256842 | E5: =C5-C$21 -> 0.086481502
A6: BH Invest | B6: ='Données financières brutes'!L6/'Données financières brutes'!D6 -> 0.79024569 | C6: ='Données financières brutes'!M6/'Données financières brutes'!E6 -> 0.34662524 | D6: =B6-B$21 -> 0.28912448 | E6: =C6-C$21 -> -0.074164144
A7: BMCE | B7: ='Données financières brutes'!L7/'Données financières brutes'!D7 -> 0.52313725 | C7: ='Données financières brutes'!M7/'Données financières brutes'!E7 -> 0.44824708 | D7: =B7-B$21 -> 0.022016042 | E7: =C7-C$21 -> 0.027457698
A8: BNA Capitaux | B8: ='Données financières brutes'!L8/'Données financières brutes'!D8 -> 0.7818556 | C8: ='Données financières brutes'!M8/'Données financières brutes'!E8 -> 0.31360656 | D8: =B8-B$21 -> 0.28073439 | E8: =C8-C$21 -> -0.10718282
A9: BTK Conseil | B9: ='Données financières brutes'!L9/'Données financières brutes'!D9 -> 0.4125 | C9: ='Données financières brutes'!M9/'Données financières brutes'!E9 -> 0.41526611 | D9: =B9-B$21 -> -0.088621212 | E9: =C9-C$21 -> -0.0055232744
A10: CGI | B10: ='Données financières brutes'!L10/'Données financières brutes'!D10 -> 0.71576763 | C10: ='Données financières brutes'!M10/'Données financières brutes'!E10 -> 0.54880694 | D10: =B10-B$21 -> 0.21464642 | E10: =C10-C$21 -> 0.12801756
A11: FINACORP | B11: ='Données financières brutes'!L11/'Données financières brutes'!D11 -> 2.2152589 | C11: ='Données financières brutes'!M11/'Données financières brutes'!E11 -> 0.88461538 | D11: =B11-B$21 -> 1.7141376 | E11: =C11-C$21 -> 0.463826
A12: MAC SA | B12: ='Données financières brutes'!L12/'Données financières brutes'!D12 -> 0.21324975 | C12: ='Données financières brutes'!M12/'Données financières brutes'!E12 -> 0.31029567 | D12: =B12-B$21 -> -0.28787147 | E12: =C12-C$21 -> -0.11049371
A13: MAXULA | B13: ='Données financières brutes'!L13/'Données financières brutes'!D13 -> 0.42753885 | C13: ='Données financières brutes'!M13/'Données financières brutes'!E13 -> 0.51237624 | D13: =B13-B$21 -> -0.073582362 | E13: =C13-C$21 -> 0.091586857
A14: MCP | B14: ='Données financières brutes'!L14/'Données financières brutes'!D14 -> 0.82287449 | C14: ='Données financières brutes'!M14/'Données financières brutes'!E14 -> 0.75025484 | D14: =B14-B$21 -> 0.32175328 | E14: =C14-C$21 -> 0.32946546
... A20: Union Capital | B20: ='Données financières brutes'!L20/'Données financières brutes'!D20 -> 0.2440678 | C20: ='Données financières brutes'!M20/'Données financières brutes'!E20 -> 0.36899423 | D20: =B20-B$21 -> -0.25705342 | E20: =C20-C$21 -> -0.051795146
A21: Moyenne | B21: ='Données financières brutes'!L21/'Données financières brutes'!D21 -> 0.50112121 | C21: ='Données financières brutes'!M21/'Données financières brutes'!E21 -> 0.42078938

Sheet Marge Nette
A1: Société | B1: Marge Nette (%) | D1: vs Moyenne
B2: 2025 | C2: 2024 | D2: 2025 | E2: 2024
A3: Amen Invest | B3: ='Données financières brutes'!F3/'Données financières brutes'!D3 -> 0.35540269 | C3: ='Données financières brutes'!G3/'Données financières brutes'!E3 -> 0.22310757 | D3: =B3-B$21 -> 0.10121334 | E3: =C3-C$21 -> -0.10173987
A4: AFC | B4: ='Données financières brutes'!F4/'Données financières brutes'!D4 -> 0.1687464 | C4: ='Données financières brutes'!G4/'Données financières brutes'!E4 -> 0.10763889 | D4: =B4-B$21 -> -0.085442957 | E4: =C4-C$21 -> -0.21720855
A5: Attijari Intermed. | B5: ='Données financières brutes'!F5/'Données financières brutes'!D5 -> -0.14014252 | C5: ='Données financières brutes'!G5/'Données financières brutes'!E5 -> 0.10821779 | D5: =B5-B$21 -> -0.39433188 | E5: =C5-C$21 -> -0.21662965
A6: BH Invest | B6: ='Données financières brutes'!F6/'Données financières brutes'!D6 -> 0.19838651 | C6: ='Données financières brutes'!G6/'Données financières brutes'!E6 -> 0.39012601 | D6: =B6-B$21 -> -0.055802853 | E6: =C6-C$21 -> 0.065278579
A7: BMCE | B7: ='Données financières brutes'!F7/'Données financières brutes'!D7 -> -0.24941176 | C7: ='Données financières brutes'!G7/'Données financières brutes'!E7 -> 0.14691152 | D7: =B7-B$21 -> -0.50360112 | E7: =C7-C$21 -> -0.17793592
A8: BNA Capitaux | B8: ='Données financières brutes'!F8/'Données financières brutes'!D8 -> 0.35551363 | C8: ='Données financières brutes'!G8/'Données financières brutes'!E8 -> 0.56368852 | D8: =B8-B$21 -> 0.10132428 | E8: =C8-C$21 -> 0.23884109
A9: BTK Conseil | B9: ='Données financières brutes'!F9/'Données financières brutes'!D9 -> 0.28988095 | C9: ='Données financières brutes'!G9/'Données financières brutes'!E9 -> 0.37955182 | D9: =B9-B$21 -> 0.035691595 | E9: =C9-C$21 -> 0.054704385
A10: CGI | B10: ='Données financières brutes'!F10/'Données financières brutes'!D10 -> 0.17842324 | C10: ='Données financières brutes'!G10/'Données financières brutes'!E10 -> 0.29934924 | D10: =B10-B$21 -> -0.075766121 | E10: =C10-C$21 -> -0.025498195
A11: FINACORP | B11: ='Données financières brutes'!F11/'Données financières brutes'!D11 -> -2.6457766 | C11: ='Données financières brutes'!G11/'Données financières brutes'!E11 -> -0.034855769 | D11: =B11-B$21 -> -2.8999659 | E11: =C11-C$21 -> -0.3597032
A12: MAC SA | B12: ='Données financières brutes'!F12/'Données financières brutes'!D12 -> 0.2395798 | C12: ='Données financières brutes'!G12/'Données financières brutes'!E12 -> 0.13680042 | D12: =B12-B$21 -> -0.014609554 | E12: =C12-C$21 -> -0.18804701
A13: MAXULA | B13: ='Données financières brutes'!F13/'Données financières brutes'!D13 -> 0.074810264 | C13: ='Données financières brutes'!G13/'Données financières brutes'!E13 -> -0.13267327 | D13: =B13-B$21 -> -0.17937909 | E13: =C13-C$21 -> -0.4575207
A14: MCP | B14: ='Données financières brutes'!F14/'Données financières brutes'!D14 -> -0.1791498 | C14: ='Données financières brutes'!G14/'Données financières brutes'!E14 -> 0.21508665 | D14: =B14-B$21 -> -0.43333916 | E14: =C14-C$21 -> -0.10976079
... A20: Union Capital | B20: ='Données financières brutes'!F20/'Données financières brutes'!D20 -> 0.63864407 | C20: ='Données financières brutes'!G20/'Données financières brutes'!E20 -> 0.77450352 | D20: =B20-B$21 -> 0.38445471 | E20: =C20-C$21 -> 0.44965609
A21: Moyenne | B21: ='Données financières brutes'!F21/'Données financières brutes'!D21 -> 0.25418936 | C21: ='Données financières brutes'!G21/'Données financières brutes'!E21 -> 0.32484744

Sheet Poids Immob. Fin.
A1: Société | B1: Poids Immob. Fin. (%) | D1: vs Moyenne
B2: 2025 | C2: 2024 | D2: 2025 | E2: 2024
A3: Amen Invest | B3: ='Données financières brutes'!J3/'Données financières brutes'!H3 -> 0.12248374 | C3: ='Données financières brutes'!K3/'Données financières brutes'!I3 -> 0.16177093 | D3: =B3-B$21 -> 0.0007869354 | E3: =C3-C$21 -> 0.029970397
A4: AFC | B4: ='Données financières brutes'!J4/'Données financières brutes'!H4 -> 0.068226894 | C4: ='Données financières brutes'!K4/'Données financières brutes'!I4 -> 0.14105642 | D4: =B4-B$21 -> -0.053469912 | E4: =C4-C$21 -> 0.0092558894
A5: Attijari Intermed. | B5: ='Données financières brutes'!J5/'Données financières brutes'!H5 -> 0.061343836 | C5: ='Données financières brutes'!K5/'Données financières brutes'!I5 -> 0.062592702 | D5: =B5-B$21 -> -0.06035297 | E5: =C5-C$21 -> -0.069207831
A6: BH Invest | B6: ='Données financières brutes'!J6/'Données financières brutes'!H6 -> 0.22217674 | C6: ='Données financières brutes'!K6/'Données financières brutes'!I6 -> 0.26704545 | D6: =B6-B$21 -> 0.10047994 | E6: =C6-C$21 -> 0.13524492
A7: BMCE | B7: ='Données financières brutes'!J7/'Données financières brutes'!H7 -> 0.032551551 | C7: ='Données financières brutes'!K7/'Données financières brutes'!I7 -> 0.17069852 | D7: =B7-B$21 -> -0.089145254 | E7: =C7-C$21 -> 0.038897985
A8: BNA Capitaux | B8: ='Données financières brutes'!J8/'Données financières brutes'!H8 -> 0.070867447 | C8: ='Données financières brutes'!K8/'Données financières brutes'!I8 -> 0.067700706 | D8: =B8-B$21 -> -0.050829359 | E8: =C8-C$21 -> -0.064099828
A9: BTK Conseil | B9: ='Données financières brutes'!J9/'Données financières brutes'!H9 -> 0.17313167 | C9: ='Données financières brutes'!K9/'Données financières brutes'!I9 -> 0.21657116 | D9: =B9-B$21 -> 0.051434867 | E9: =C9-C$21 -> 0.084770623
A10: CGI | B10: ='Données financières brutes'!J10/'Données financières brutes'!H10 -> 0.19019231 | C10: ='Données financières brutes'!K10/'Données financières brutes'!I10 -> 0.30860034 | D10: =B10-B$21 -> 0.068495502 | E10: =C10-C$21 -> 0.1767998
A11: FINACORP | B11: ='Données financières brutes'!J11/'Données financières brutes'!H11 -> 0.17767733 | C11: ='Données financières brutes'!K11/'Données financières brutes'!I11 -> 0.140625 | D11: =B11-B$21 -> 0.055980524 | E11: =C11-C$21 -> 0.0088244668
A12: MAC SA | B12: ='Données financières brutes'!J12/'Données financières brutes'!H12 -> 0.084286175 | C12: ='Données financières brutes'!K12/'Données financières brutes'!I12 -> 0.066536466 | D12: =B12-B$21 -> -0.037410631 | E12: =C12-C$21 -> -0.065264067
A13: MAXULA | B13: ='Données financières brutes'!J13/'Données financières brutes'!H13 -> 0.3893368 | C13: ='Données financières brutes'!K13/'Données financières brutes'!I13 -> 0.42528025 | D13: =B13-B$21 -> 0.26764 | E13: =C13-C$21 -> 0.29347972
A14: MCP | B14: ='Données financières brutes'!J14/'Données financières brutes'!H14 -> 0.15689001 | C14: ='Données financières brutes'!K14/'Données financières brutes'!I14 -> 0.14566263 | D14: =B14-B$21 -> 0.035193207 | E14: =C14-C$21 -> 0.013862102
... A20: Union Capital | B20: ='Données financières brutes'!J20/'Données financières brutes'!H20 -> 0.078713885 | C20: ='Données financières brutes'!K20/'Données financières brutes'!I20 -> 0.091192947 | D20: =B20-B$21 -> -0.042982921 | E20: =C20-C$21 -> -0.040607586
A21: Moyenne | B21: ='Données financières brutes'!J21/'Données financières brutes'!H21 -> 0.12169681 | C21: ='Données financières brutes'!K21/'Données financières brutes'!I21 -> 0.13180053

Sheet Coeff. Exploit.
A1: Société | B1: Coeff. Exploit. (%) | D1: vs Moyenne
B2: 2025 | C2: 2024 | D2: 2025 | E2: 2024
A3: Amen Invest | B3: ='Données financières brutes'!N3/'Données financières brutes'!D3 -> 0.64860992 | C3: ='Données financières brutes'!O3/'Données financières brutes'!E3 -> 0.84143426 | D3: =B3-B$21 -> -0.23969965 | E3: =C3-C$21 -> 0.039068044
A4: AFC | B4: ='Données financières brutes'!N4/'Données financières brutes'!D4 -> 0.8875024 | C4: ='Données financières brutes'!O4/'Données financières brutes'!E4 -> 0.99603175 | D4: =B4-B$21 -> -0.00080716541 | E4: =C4-C$21 -> 0.19366553
A5: Attijari Intermed. | B5: ='Données financières brutes'!N5/'Données financières brutes'!D5 -> 1.5779889 | C5: ='Données financières brutes'!O5/'Données financières brutes'!E5 -> 1.0081163 | D5: =B5-B$21 -> 0.68967935 | E5: =C5-C$21 -> 0.20575012
A6: BH Invest | B6: ='Données financières brutes'!N6/'Données financières brutes'!D6 -> 1.1936194 | C6: ='Données financières brutes'!O6/'Données financières brutes'!E6 -> 0.59640946 | D6: =B6-B$21 -> 0.3053098 | E6: =C6-C$21 -> -0.20595676
A7: BMCE | B7: ='Données financières brutes'!N7/'Données financières brutes'!D7 -> 1.2203922 | C7: ='Données financières brutes'!O7/'Données financières brutes'!E7 -> 1.0175292 | D7: =B7-B$21 -> 0.33208259 | E7: =C7-C$21 -> 0.215163
A8: BNA Capitaux | B8: ='Données financières brutes'!N8/'Données financières brutes'!D8 -> 0.95060881 | C8: ='Données financières brutes'!O8/'Données financières brutes'!E8 -> 0.41286885 | D8: =B8-B$21 -> 0.06229925 | E8: =C8-C$21 -> -0.38949737
A9: BTK Conseil | B9: ='Données financières brutes'!N9/'Données financières brutes'!D9 -> 0.58214286 | C9: ='Données financières brutes'!O9/'Données financières brutes'!E9 -> 0.56442577 | D9: =B9-B$21 -> -0.30616671 | E9: =C9-C$21 -> -0.23794045
A10: CGI | B10: ='Données financières brutes'!N10/'Données financières brutes'!D10 -> 1.1327801 | C10: ='Données financières brutes'!O10/'Données financières brutes'!E10 -> 0.95227766 | D10: =B10-B$21 -> 0.24447052 | E10: =C10-C$21 -> 0.14991144
A11: FINACORP | B11: ='Données financières brutes'!N11/'Données financières brutes'!D11 -> 3.8201635 | C11: ='Données financières brutes'!O11/'Données financières brutes'!E11 -> 1.5865385 | D11: =B11-B$21 -> 2.9318539 | E11: =C11-C$21 -> 0.78417224
A12: MAC SA | B12: ='Données financières brutes'!N12/'Données financières brutes'!D12 -> 0.67946459 | C12: ='Données financières brutes'!O12/'Données financières brutes'!E12 -> 0.88104541 | D12: =B12-B$21 -> -0.20884498 | E12: =C12-C$21 -> 0.078679188
A13: MAXULA | B13: ='Données financières brutes'!N13/'Données financières brutes'!D13 -> 0.9194073 | C13: ='Données financières brutes'!O13/'Données financières brutes'!E13 -> 1.0871287 | D13: =B13-B$21 -> 0.031097735 | E13: =C13-C$21 -> 0.28476249
A14: MCP | B14: ='Données financières brutes'!N14/'Données financières brutes'!D14 -> 1.3248988 | C14: ='Données financières brutes'!O14/'Données financières brutes'!E14 -> 1.3567788 | D14: =B14-B$21 -> 0.43658922 | E14: =C14-C$21 -> 0.55441258
... A20: Union Capital | B20: ='Données financières brutes'!N20/'Données financières brutes'!D20 -> 0.38983051 | C20: ='Données financières brutes'!O20/'Données financières brutes'!E20 -> 0.73478539 | D20: =B20-B$21 -> -0.49847906 | E20: =C20-C$21 -> -0.067580825
A21: Moyenne | B21: ='Données financières brutes'!N21/'Données financières brutes'!D21 -> 0.88830957 | C21: ='Données financières brutes'!O21/'Données financières brutes'!E21 -> 0.80236622

Sheet Poids Prod. Placement
A1: Société | B1: Poids Prod. Placement (%) | D1: vs Moyenne
B2: 2025 | C2: 2024 | D2: 2025 | E2: 2024
A3: Amen Invest | B3: ='Données financières brutes'!R3/'Données financières brutes'!D3 -> 0.083691602 | C3: ='Données financières brutes'!S3/'Données financières brutes'!E3 -> 0.10836653 | D3: =B3-B$21 -> -0.19588245 | E3: =C3-C$21 -> -0.12414065
A4: AFC | B4: ='Données financières brutes'!R4/'Données financières brutes'!D4 -> 0.080245729 | C4: ='Données financières brutes'!S4/'Données financières brutes'!E4 -> 0.076140873 | D4: =B4-B$21 -> -0.19932832 | E4: =C4-C$21 -> -0.15636631
A5: Attijari Intermed. | B5: ='Données financières brutes'!R5/'Données financières brutes'!D5 -> 0.42359462 | C5: ='Données financières brutes'!S5/'Données financières brutes'!E5 -> 0.10043963 | D5: =B5-B$21 -> 0.14402057 | E5: =C5-C$21 -> -0.13206755
A6: BH Invest | B6: ='Données financières brutes'!R6/'Données financières brutes'!D6 -> 0.41840851 | C6: ='Données financières brutes'!S6/'Données financières brutes'!E6 -> 0.089073019 | D6: =B6-B$21 -> 0.13883446 | E6: =C6-C$21 -> -0.14343417
A7: BMCE | B7: N/D | C7: N/D | D7: N/D | E7: N/D
A8: BNA Capitaux | B8: ='Données financières brutes'!R8/'Données financières brutes'!D8 -> 0.3941005 | C8: ='Données financières brutes'!S8/'Données financières brutes'!E8 -> 0.14442623 | D8: =B8-B$21 -> 0.11452645 | E8: =C8-C$21 -> -0.088080958
A9: BTK Conseil | B9: N/D | C9: N/D | D9: N/D | E9: N/D
A10: CGI | B10: ='Données financières brutes'!R10/'Données financières brutes'!D10 -> 0.4439834 | C10: ='Données financières brutes'!S10/'Données financières brutes'!E10 -> 0.3340564 | D10: =B10-B$21 -> 0.16440935 | E10: =C10-C$21 -> 0.10154921
A11: FINACORP | B11: ='Données financières brutes'!R11/'Données financières brutes'!D11 -> 0.089918256 | C11: ='Données financières brutes'!S11/'Données financières brutes'!E11 -> 0.53725962 | D11: =B11-B$21 -> -0.18965579 | E11: =C11-C$21 -> 0.30475243
A12: MAC SA | B12: ='Données financières brutes'!R12/'Données financières brutes'!D12 -> 0.035852253 | C12: ='Données financières brutes'!S12/'Données financières brutes'!E12 -> 0.094984161 | D12: =B12-B$21 -> -0.2437218 | E12: =C12-C$21 -> -0.13752303
A13: MAXULA | B13: ='Données financières brutes'!R13/'Données financières brutes'!D13 -> 0.10697506 | C13: ='Données financières brutes'!S13/'Données financières brutes'!E13 -> 0.1 | D13: =B13-B$21 -> -0.17259899 | E13: =C13-C$21 -> -0.13250719
A14: MCP | B14: ='Données financières brutes'!R14/'Données financières brutes'!D14 -> 0.11336032 | C14: ='Données financières brutes'!S14/'Données financières brutes'!E14 -> 0.5351682 | D14: =B14-B$21 -> -0.16621373 | E14: =C14-C$21 -> 0.30266101
A15: SBT | B15: ='Données financières brutes'!R15/'Données financières brutes'!D15 -> 0.073368271 | C15: ='Données financières brutes'!S15/'Données financières brutes'!E15 -> 0.077981651 | D15: =B15-B$21 -> -0.20620578 | E15: =C15-C$21 -> -0.15452554
A16: STB Finance | B16: ='Données financières brutes'!R16/'Données financières brutes'!D16 -> 0.39387228 | C16: ='Données financières brutes'!S16/'Données financières brutes'!E16 -> 0.078687127 | D16: =B16-B$21 -> 0.11429823 | E16: =C16-C$21 -> -0.15382006
A17: Tunisie Valeurs | B17: ='Données financières brutes'!R17/'Données financières brutes'!D17 -> 0.53127778 | C17: ='Données financières brutes'!S17/'Données financières brutes'!E17 -> 0.42528033 | D17: =B17-B$21 -> 0.25170373 | E17: =C17-C$21 -> 0.19277314
A18: UFI | B18: ='Données financières brutes'!R18/'Données financières brutes'!D18 -> 1.2371643 | C18: ='Données financières brutes'!S18/'Données financières brutes'!E18 -> 0.98132327 | D18: =B18-B$21 -> 0.95759029 | E18: =C18-C$21 -> 0.74881608
A19: UIB Finance | B19: ='Données financières brutes'!R19/'Données financières brutes'!D19 -> 0.11968777 | C19: ='Données financières brutes'!S19/'Données financières brutes'!E19 -> 0.2596054 | D19: =B19-B$21 -> -0.15988628 | E19: =C19-C$21 -> 0.027098212
A20: Union Capital | B20: ='Données financières brutes'!R20/'Données financières brutes'!D20 -> 0.14881356 | C20: ='Données financières brutes'!S20/'Données financières brutes'!E20 -> 0.58680333 | D20: =B20-B$21 -> -0.13076049 | E20: =C20-C$21 -> 0.35429614
A21: Moyenne | B21: ='Données financières brutes'!R21/'Données financières brutes'!D21 -> 0.27957405 | C21: ='Données financières brutes'!S21/'Données financières brutes'!E21 -> 0.23250719

Sheet Poids Prod. Plac. Rés
A1: Société | B1: Poids Prod. Placement (%) | D1: vs Moyenne
B2: 2025 | C2: 2024 | D2: 2025 | E2: 2024
A3: Amen Invest | B3: ='Données financières brutes'!R3/'Données financières brutes'!F3 -> 0.23548387 | C3: ='Données financières brutes'!S3/'Données financières brutes'!G3 -> 0.48571429 | D3: =B3-B$21 -> -0.86438141 | E3: =C3-C$21 -> -0.23002844
A4: AFC | B4: ='Données financières brutes'!R4/'Données financières brutes'!F4 -> 0.47554039 | C4: ='Données financières brutes'!S4/'Données financières brutes'!G4 -> 0.70737327 | D4: =B4-B$21 -> -0.6243249 | E4: =C4-C$21 -> -0.008369449
A5: Attijari Intermed. | B5: ='Données financières brutes'!R5/'Données financières brutes'!F5 -> -3.0225989 | C5: ='Données financières brutes'!S5/'Données financières brutes'!G5 -> 0.928125 | D5: =B5-B$21 -> -4.1224642 | E5: =C5-C$21 -> 0.21238228
A6: BH Invest | B6: ='Données financières brutes'!R6/'Données financières brutes'!F6 -> 2.1090573 | C6: ='Données financières brutes'!S6/'Données financières brutes'!G6 -> 0.22831858 | D6: =B6-B$21 -> 1.009192 | E6: =C6-C$21 -> -0.48742414
A7: BMCE | B7: N/D | C7: N/D | D7: N/D | E7: N/D
A8: BNA Capitaux | B8: ='Données financières brutes'!R8/'Données financières brutes'!F8 -> 1.1085384 | C8: ='Données financières brutes'!S8/'Données financières brutes'!G8 -> 0.25621637 | D8: =B8-B$21 -> 0.0086730684 | E8: =C8-C$21 -> -0.45952635
A9: BTK Conseil | B9: N/D | C9: N/D | D9: N/D | E9: N/D
A10: CGI | B10: ='Données financières brutes'!R10/'Données financières brutes'!F10 -> 2.4883721 | C10: ='Données financières brutes'!S10/'Données financières brutes'!G10 -> 1.115942 | D10: =B10-B$21 -> 1.3885068 | E10: =C10-C$21 -> 0.40019931
A11: FINACORP | B11: ='Données financières brutes'!R11/'Données financières brutes'!F11 -> -0.033985582 | C11: ='Données financières brutes'!S11/'Données financières brutes'!G11 -> -15.413793 | D11: =B11-B$21 -> -1.1338509 | E11: =C11-C$21 -> -16.129536
A12: MAC SA | B12: ='Données financières brutes'!R12/'Données financières brutes'!F12 -> 0.14964639 | C12: ='Données financières brutes'!S12/'Données financières brutes'!G12 -> 0.69432651 | D12: =B12-B$21 -> -0.95021889 | E12: =C12-C$21 -> -0.021416206
A13: MAXULA | B13: ='Données financières brutes'!R13/'Données financières brutes'!F13 -> 1.4299517 | C13: ='Données financières brutes'!S13/'Données financières brutes'!G13 -> -0.75373134 | D13: =B13-B$21 -> 0.33008641 | E13: =C13-C$21 -> -1.4694741
A14: MCP | B14: ='Données financières brutes'!R14/'Données financières brutes'!F14 -> -0.63276836 | C14: ='Données financières brutes'!S14/'Données financières brutes'!G14 -> 2.4881517 | D14: =B14-B$21 -> -1.7326336 | E14: =C14-C$21 -> 1.7724089
A15: SBT | B15: ='Données financières brutes'!R15/'Données financières brutes'!F15 -> 0.18075117 | C15: ='Données financières brutes'!S15/'Données financières brutes'!G15 -> 0.29394813 | D15: =B15-B$21 -> -0.91911411 | E15: =C15-C$21 -> -0.42179459
A16: STB Finance | B16: ='Données financières brutes'!R16/'Données financières brutes'!F16 -> 4.0416667 | C16: ='Données financières brutes'!S16/'Données financières brutes'!G16 -> 0.21321321 | D16: =B16-B$21 -> 2.9418014 | E16: =C16-C$21 -> -0.50252951
A17: Tunisie Valeurs | B17: ='Données financières brutes'!R17/'Données financières brutes'!F17 -> 2.8907841 | C17: ='Données financières brutes'!S17/'Données financières brutes'!G17 -> 1.5587521 | D17: =B17-B$21 -> 1.7909188 | E17: =C17-C$21 -> 0.84300938
A18: UFI | B18: ='Données financières brutes'!R18/'Données financières brutes'!F18 -> 1.1901219 | C18: ='Données financières brutes'!S18/'Données financières brutes'!G18 -> 0.98641901 | D18: =B18-B$21 -> 0.090256644 | E18: =C18-C$21 -> 0.27067629
A19: UIB Finance | B19: ='Données financières brutes'!R19/'Données financières brutes'!F19 -> 0.45394737 | C19: ='Données financières brutes'!S19/'Données financières brutes'!G19 -> 0.73964497 | D19: =B19-B$21 -> -0.64591791 | E19: =C19-C$21 -> 0.02390225
A20: Union Capital | B20: ='Données financières brutes'!R20/'Données financières brutes'!F20 -> 0.23301486 | C20: ='Données financières brutes'!S20/'Données financières brutes'!G20 -> 0.75765095 | D20: =B20-B$21 -> -0.86685042 | E20: =C20-C$21 -> 0.04190823
A21: Moyenne | B21: ='Données financières brutes'!R21/'Données financières brutes'!F21 -> 1.0998653 | C21: ='Données financières brutes'!S21/'Données financières brutes'!G21 -> 0.71574272

Sheet Comp. CA
A1: Amen Invest | B1: 2025 | C1: 2024 | E1: BNA Capitaux | F1: 2025 | G1: 2024 | I1: MAXULA | J1: 2025 | K1: 2024 | M1: Tunisie Valeurs | N1: 2025 | O1: 2024
A2: Commissions sur les transactions boursières et de gestion des comptes titres | B2: 1.112 | C2: 0.799 | E2: Courtage sur clients | F2: 0.913 | G2: 0.532 | I2: Courtage / opération transaction | J2: 0.431 | K2: 0.242 | M2: Commissions sur les transactions boursières et gestion des comptes titres | N2: 6.454 | O2: 3.54
A3: Commissions sur placement d’obligations | B3: 0.343 | C3: 0.634 | E3: Commission de gestion OPCVM | F3: 3.195 | G3: 2.503 | I3: Produits / Fermetures de comptes | J3: 0.022 | K3: 0.002 | M3: Commissions sur placements d'obligations | N3: 0.785 | O3: 4.068
A4: Commissions de Gestion des OPCVM | B4: 0.583 | C4: 0.385 | E4: Commission sur service à l'émetteur | F4: 0.155 | G4: 0.147 | I4: Produits / Frais de garde et de gestion | J4: 1.092 | K4: 0.723 | M4: Commission de courtage OPCVM | N4: 0.072 | O4: 0.066
A5: Commissions de Gestion des comptes gérés | B5: 0.798 | C5: 0.277 | E5: Commission de placement d'emprunt | F5: 0.67 | G5: 8.076 | I5: Produits / Frais de gestion des OPVCM | J5: 1.221 | K5: 1.053 | M5: Commissions de distribution OPCVM | N5: 8.292 | O5: 7.121
A6: Commissions sur tenue de registre des actionnaires | B6: 0.015 | C6: 0.016 | E6: Commission de tenue de comptes | F6: 0.419 | G6: 0.446 | I6: Total | J6: =SUM(J2:J5) -> 2.766 | K6: =SUM(K2:K5) -> 2.02 | M6: Etudes et assistances | N6: 0.33 | O6: 0.225
A7: Assistance administrative et comptable des OPCVMs | B7: 0.476 | C7: 0.398 | E7: Commission d'encaissement de coupons | F7: 0.093 | G7: 0.083 | M7: Droits de garde | N7: 3.187 | O7: 2.801
A8: Honoraires d'études | B8: 0.16 | C8: 0 | E8: Commission de remboursement emprunt obligataire | F8: 0.085 | G8: 0.089 | I8: MCP | J8: 2025 | K8: 2024 | M8: Revenus Mise à disposition du personnel | N8: 1.841 | O8: 1.413
A9: Total | B9: =SUM(B2:B8) -> 3.487 | C9: =SUM(C2:C8) -> 2.509 | E9: Commission de distribution OPCVM | F9: 0.25 | G9: 0.228 | I9: études, montages et prestation de services | J9: 0.497 | K9: 0.292 | M9: Exportation de services | N9: 0 | O9: 0.017
E10: étude et Ingénierie | F10: 0.027 | G10: 0.072 | I10: Commission de superformance | J10: 0.082 | K10: 0.069 | M10: Autres revenus | N10: 0.218 | O10: 0.18
A11: Attijari Itermediation | B11: 2025 | C11: 2024 | E11: Autres revenus (Contrats gérés, com. distribution, clôtures cptes) | F11: 0.02 | G11: 0.019 | I11: Courtage JB | J11: 0.105 | K11: 0.052 | M11: Total | N11: =SUM(N2:N10) -> 21.179 | O11: =SUM(O2:O10) -> 19.431
A12: Commissions sur émissions des emprunts | B12: 0 | C12: 2.117 | E12: Total | F12: =SUM(F2:F11) -> 5.827 | G12: =SUM(G2:G11) -> 12.195 | I12: Commission de placements | J12: 0 | K12: 0.142
A13: Commissions de gestion et de garde | B13: 0.13 | C13: 0.122 | I13: Courtage enregistrement | J13: 0.079 | K13: 0.25 | M13: UIB | N13: 2025 | O13: 2024
A14: Commissions sur achat en bourse | B14: 0.261 | C14: 0.187 | E14: BTK Conseil | F14: 2025 | G14: 2024 | I14: Autres revenus | J14: 0.213 | K14: 0.157 | M14: Commissions de gestion OPCVM | N14: 0.898 | O14: 0.704
A15: Commissions sur vente en bourse | B15: 0.247 | C15: 0.216 | E15: Courtages | F15: 0.156 | G15: 0.11 | I15: Autres produits d'exploitation | J15: 0.01 | K15: 0.016 | M15: Commission de courtage | N15: 0.059 | O15: 0.046
A16: Comissions sur OPV | B16: 0 | C16: 0 | E16: Commissions de placement | F16: 0.505 | G16: 0.396 | I16: Total | J16: =SUM(J9:J15) -> 0.986 | K16: =SUM(K9:K15) -> 0.978 | M16: Commissions sur les transactions boursières et de gestion comptes titres | N16: 0.073 | O16: 0.064
A17: Commissions sur encaissement dividendes | B17: 0.158 | C17: 0.147 | E17: Commissions de montage & de gestion d'emprunts | F17: 0.005 | G17: 0.003 | M17: Commissions de tenue de comptes | N17: 0.016 | O17: 0.016
A18: Commission / études | B18: 0.068 | C18: 0.047 | E18: Commissions prestation de service (conseil financier) | F18: 0 | G18: 0.4 | I18: SBT | J18: 2025 | K18: 2024 | M18: Commissions de placement d'emprunts obligataires | N18: 0.002 | O18: 0.028
A19: Frais d'ouverture et de clôture | B19: 0.001 | C19: 0.001 | E19: Commissions de gestion SICAV | F19: 0.807 | G19: 0.323 | I19: Courtages sur opération de bourse | J19: 0.586 | K19: 0.263 | M19: Total | N19: =SUM(N14:N18) -> 1.048 | O19: =SUM(O14:O18) -> 0.858
A20: Commission de transfert | B20: 0 | C20: 0 | E20: Commissions de gestion FCP | F20: 0.048 | G20: 0.019 | I20: Commission de gestion SICAV CROISSANCE | J20: 0.103 | K20: 0.091
A21: Autres produits | B21: 0.091 | C21: 0.106 | E21: Commissions de gestion portefeuilles clients | F21: 0.02 | G21: 0.034 | I21: Commission de gestion SICAV RENDEMENT | J21: 0.877 | K21: 0.724 | M21: Union Capital | N21: 2025 | O21: 2024
A22: Commissions de gestion / ATG | B22: 0.295 | C22: 0 | E22: Commissions d'ouverture et de clôture de comptes | F22: 0.004 | G22: 0.003 | I22: Commission de gestion FCP CEA BT | J22: 0.287 | K22: 0.21 | M22: Commissions activité Bourse | N22: 0.663 | O22: 0.354
A23: Total | B23: =SUM(B12:B22) -> 1.251 | C23: =SUM(C12:C22) -> 2.943 | E23: Diverses commissions | F23: 0.014 | G23: 0.015 | I23: Commission de gestion SICAV | J23: 0 | K23: 0 | M23: Commissions de Tenue de registre | N23: 0.022 | O23: 0.019
E24: Total | F24: =SUM(F15:F23) -> 1.559 | G24: =SUM(G15:G23) -> 1.303 | I24: CAPITALISATION PLUS | J24: 0.235 | K24: 0.011 | M24: Commissions de placement des EO / EMP NAT | N24: 0.474 | O24: 0.044
A25: AFC | B25: 2025 | C25: 2024 | I25: Total | J25: =SUM(J19:J24) -> 2.088 | K25: =SUM(K19:K24) -> 1.299 | M25: Commissions T.clearing | N25: 0.0004 | O25: 0
A26: Courtage électronique | B26: 0.527 | C26: 0.333 | E26: CGI | F26: 2025 | G26: 2024 | M26: Assistance Montage et conduite | N26: 0.034 | O26: 0.011
A27: Courtage hors cote | B27: 0.107 | C27: 0.037 | E27: Commissions pour services financiers | F27: 0.041 | G27: 0.013 | I27: STB | J27: 2025 | K27: 2024 | M27: Frais de Gestion OPCVM | N27: 1.51 | O27: 0.964
A28: Courtage sur OPV | B28: 0 | C28: 0 | E28: Commissions de transactions boursières | F28: 0.232 | G28: 0.147 | I28: Commissions sur les transactions boursières | J28: 0.318 | K28: 0.281 | M28: Frais de Distributeurs OPCVM | N28: 0.161 | O28: 0.061
A29: Commissions diverses compte titres (FTC ect…) | B29: 0.174 | C29: 0.17 | E29: Commissions de placements de billets de trésorerie | F29: 0.151 | G29: 0.223 | I29: Commissions de gestion des comptes titres | J29: 0.104 | K29: 0.083 | M29: Frais de Gestion des filiales | N29: 0.013 | O29: 0.052
A30: Fonds FCP & SICAV | B30: 3.897 | C30: 2.309 | E30: Commissions d'études | F30: 0 | G30: 0.02 | I30: Commissions sur détachement de dividendes | J30: 0.073 | K30: 0.057 | M30: Frais de Gestion du portefeuille | N30: 0.061 | O30: 0.045
A31: Commissions de placement | B31: 0.337 | C31: 1.087 | E31: Commissions de gestion des OPCVM | F31: 0.052 | G31: 0.051 | I31: Commissions de tenue de compte | J31: 0.094 | K31: 0.09 | M31: Frais de dépositaires UTP | N31: 0.008 | O31: 0.008
A32: Produits sur comptes gérés | B32: 0.026 | C32: 0 | E32: Jetons de présence | F32: 0.004 | G32: 0.004 | I32: Commissions sur transfert de compte | J32: 0.0001 | K32: 0 | M32: Total | N32: =SUM(N22:N31) -> 2.9464 | O32: =SUM(O22:O31) -> 1.558
A33: Produits d'études | B33: 0.065 | C33: 0.014 | E33: Total | F33: =SUM(F27:F32) -> 0.48 | G33: =SUM(G27:G32) -> 0.458 | I33: Commissions d'ouverture et de clôture de compte | J33: 0.029 | K33: 0.014
A34: Produits tenue de registre | B34: 0.066 | C34: 0.075 | I34: Commissions de placements | J34: 0 | K34: 9.474 | M34: UFI | N34: 2025 | O34: 2024
A35: Divers | B35: 0.006 | C35: 0.003 | E35: MAC SA | F35: 2025 | G35: 2024 | I35: Commissions de gestion des OPCVM | J35: 1.956 | K35: 1.612 | M35: Bourse | N35: 0.051 | O35: 0.068
A36: Total | B36: =SUM(B26:B35) -> 5.205 | C36: =SUM(C26:C35) -> 4.028 | E36: Commissions sur les transactions boursières | F36: 5.885 | G36: 3.282 | I36: Commissions de tenue de registres | J36: 0.052 | K36: 0.045 | M36: Commissions de gestion | N36: 3.896 | O36: 3.646
E37: Commissions de gestion des comptes titres | F37: 0.479 | G37: 0.531 | I37: Commissions sur détachement des coupons | J37: 0.03 | K37: 0.027 | M37: Assistance | N37: 0.578 | O37: 0.533
A38: BH Invest | B38: 2025 | C38: 2024 | E38: Commissions de tenue de comptes | F38: 0.754 | G38: 0.382 | I38: Autres | J38: 0.026 | K38: 0.017 | M38: Dividendes | N38: 0.101 | O38: 0.401
A39: Retrocession des commissions gestion SICAV | B39: -0.004 | C39: -3.059 | E39: Commissions sur transfert de comptes | F39: 0.02 | G39: 0 | I39: Total | J39: =SUM(J28:J38) -> 2.6821 | K39: =SUM(K28:K38) -> 11.7 | M39: Jetons de présence | N39: 0.013 | O39: 0.014
A40: Produits sur opérations avec la client | B40: 0.193 | C40: 0.119 | E40: Commissions de SUCCES | F40: 11.518 | G40: 0.641 | M40: Commissions rétrocédées | N40: 0.0002 | O40: 0.362
...

Sheet RECAP
A2: Détail chiffre d'affaires (en MD) | B2: AMEN INVEST | D2: BNA Capitaux | F2: MAXULA | H2: TUNISIE VALEURS | J2: ATTIJARI INTER | L2: BTK CONSEIL | N2: MCP | P2: UIB FINANCE | R2: AFC | T2: CGI | V2: STB FINANCE | X2: UNION CAPITAL | Z2: BH INVEST | AB2: MAC SA | AD2: SBT | AF2: BMCE | AH2: FINACORP | AJ2: UFI | AL2: TOTAL
B3: 2025 | C3: 2024 | D3: 2025 | E3: 2024 | F3: 2025 | G3: 2024 | H3: 2025 | I3: 2024 | J3: 2025 | K3: 2024 | L3: 2025 | M3: 2024 | N3: 2025 | O3: 2024 | P3: 2025 | Q3: 2024 | R3: 2025 | S3: 2024 | T3: 2025 | U3: 2024 | V3: 2025 | W3: 2024 | X3: 2025 | Y3: 2024 | Z3: 2025 | AA3: 2024 | AB3: 2025 | AC3: 2024 | AD3: 2025 | AE3: 2024 | AF3: 2025 | AG3: 2024 | AH3: 2025 | AI3: 2024 | AJ3: 2025 | AK3: 2024 | AL3: 2025 | AM3: 2024
A4: Commission de gestion OPCVM | B4: ='Comp. CA'!B4+'Comp. CA'!B7 -> 1.059 | C4: ='Comp. CA'!C4+'Comp. CA'!C7 -> 0.783 | D4: ='Comp. CA'!F3+'Comp. CA'!F9 -> 3.445 | E4: ='Comp. CA'!G3+'Comp. CA'!G9 -> 2.731 | F4: ='Comp. CA'!J5 -> 1.221 | G4: ='Comp. CA'!K5 -> 1.053 | H4: =+'Comp. CA'!N5 -> 8.292 | I4: =+'Comp. CA'!O5 -> 7.121 | J4: 0 | K4: 0 | L4: =+'Comp. CA'!F19+'Comp. CA'!F20 -> 0.855 | M4: =+'Comp. CA'!G19+'Comp. CA'!G20 -> 0.342 | N4: ='Comp. CA'!J14 -> 0.213 | O4: ='Comp. CA'!K14 -> 0.157 | P4: ='Comp. CA'!N14 -> 0.898 | Q4: ='Comp. CA'!O14 -> 0.704 | R4: ='Comp. CA'!B30 -> 3.897 | S4: ='Comp. CA'!C30 -> 2.309 | T4: =+'Comp. CA'!F31 -> 0.052 | U4: =+'Comp. CA'!G31 -> 0.051 | V4: ='Comp. CA'!J35 -> 1.956 | W4: ='Comp. CA'!K35 -> 1.612 | X4: =+'Comp. CA'!N27+'Comp. CA'!N28 -> 1.671 | Y4: =+'Comp. CA'!O27+'Comp. CA'!O28 -> 1.025 | Z4: =+'Comp. CA'!B53+'Comp. CA'!B54 -> 1.217 | AA4: =+'Comp. CA'!C53+'Comp. CA'!C54 -> 0.964 | AB4: =+'Comp. CA'!F43+'Comp. CA'!F44+'Comp. CA'!F45 -> 9.013 | AC4: =+'Comp. CA'!G43+'Comp. CA'!G44+'Comp. CA'!G45 -> 7.211 | AD4: =+'Comp. CA'!J20+'Comp. CA'!J21+'Comp. CA'!J22+'Comp. CA'!J24 -> 1.502 | AE4: =+'Comp. CA'!K20+'Comp. CA'!K21+'Comp. CA'!K22+'Comp. CA'!K24 -> 1.036 | AF4: ='Comp. CA'!J42 -> 0.107 | AG4: ='Comp. CA'!K42 -> 0.1 | AH4: ='Comp. CA'!N47 -> 0.135 | AI4: ='Comp. CA'!O47 -> 0.109 | AJ4: =+'Comp. CA'!N36 -> 3.896 | AK4: =+'Comp. CA'!O36 -> 3.646 | AL4: =SUM(B4,D4,F4,H4,J4,L4,N4,P4,R4,T4,V4,X4,Z4,AB4,AD4,AF4,AH4,AJ4) -> 39.429 | AM4: =SUM(C4,E4,G4,I4,K4,M4,O4,Q4,S4,U4,W4,Y4,AA4,AC4,AE4,AG4,AI4,AK4) -> 30.954 | AN4: =+AL4/$AL$9 -> 0.43865478
A5: Commission de courtage | B5: ='Comp. CA'!B2 -> 1.112 | C5: ='Comp. CA'!C2 -> 0.799 | D5: ='Comp. CA'!F2 -> 0.913 | E5: ='Comp. CA'!G2 -> 0.532 | F5: ='Comp. CA'!J2 -> 0.431 | G5: ='Comp. CA'!K2 -> 0.242 | H5: ='Comp. CA'!N2+'Comp. CA'!N4+'Comp. CA'!N9 -> 6.526 | I5: ='Comp. CA'!O2+'Comp. CA'!O4+'Comp. CA'!O9 -> 3.623 | J5: ='Comp. CA'!B14+'Comp. CA'!B15 -> 0.508 | K5: ='Comp. CA'!C14+'Comp. CA'!C15 -> 0.403 | L5: ='Comp. CA'!F15 -> 0.156 | M5: ='Comp. CA'!G15 -> 0.11 | N5: ='Comp. CA'!J11+'Comp. CA'!J13 -> 0.184 | O5: ='Comp. CA'!K11+'Comp. CA'!K13 -> 0.302 | P5: ='Comp. CA'!N15 -> 0.059 | Q5: ='Comp. CA'!O15 -> 0.046 | R5: ='Comp. CA'!B26+'Comp. CA'!B27 -> 0.634 | S5: ='Comp. CA'!C26+'Comp. CA'!C27 -> 0.37 | T5: ='Comp. CA'!F28 -> 0.232 | U5: ='Comp. CA'!G28 -> 0.147 | V5: ='Comp. CA'!J28 -> 0.318 | W5: ='Comp. CA'!K28 -> 0.281 | X5: ='Comp. CA'!N22 -> 0.663 | Y5: ='Comp. CA'!O22 -> 0.354 | Z5: ='Comp. CA'!B40+'Comp. CA'!B41 -> 0.21 | AA5: ='Comp. CA'!C40+'Comp. CA'!C41 -> 0.126 | AB5: ='Comp. CA'!F36 -> 5.885 | AC5: ='Comp. CA'!G36 -> 3.282 | AD5: ='Comp. CA'!J19 -> 0.586 | AE5: ='Comp. CA'!K19 -> 0.263 | AF5: ='Comp. CA'!J43+'Comp. CA'!J48 -> 0.315 | AG5: ='Comp. CA'!K43+'Comp. CA'!K48 -> 0.245 | AH5: ='Comp. CA'!N44+'Comp. CA'!N50 -> 0.123 | AI5: ='Comp. CA'!O44+'Comp. CA'!O50 -> 0.245 | AJ5: ='Comp. CA'!N35 -> 0.051 | AK5: ='Comp. CA'!O35 -> 0.068 | AL5: =SUM(B5,D5,F5,H5,J5,L5,N5,P5,R5,T5,V5,X5,Z5,AB5,AD5,AF5,AH5,AJ5) -> 18.906 | AM5: =SUM(C5,E5,G5,I5,K5,M5,O5,Q5,S5,U5,W5,Y5,AA5,AC5,AE5,AG5,AI5,AK5) -> 11.438 | AN5: =+AL5/$AL$9 -> 0.21033268 | AP5: =H5+AB5 -> 12.411 | AQ5: =AP5/AL5 -> 0.65645827
A6: Commission sur transaction boursière | B6: ='Comp. CA'!B5 -> 0.798 | C6: ='Comp. CA'!C5 -> 0.277 | D6: ='Comp. CA'!F6+'Comp. CA'!F7+'Comp. CA'!F8 -> 0.597 | E6: ='Comp. CA'!G6+'Comp. CA'!G7+'Comp. CA'!G8 -> 0.618 | F6: ='Comp. CA'!J3+'Comp. CA'!J4 -> 1.114 | G6: ='Comp. CA'!K3+'Comp. CA'!K4 -> 0.725 | H6: ='Comp. CA'!N7+'Comp. CA'!N10 -> 3.405 | I6: ='Comp. CA'!O7+'Comp. CA'!O10 -> 2.981 | J6: =+'Comp. CA'!B13+'Comp. CA'!B17+'Comp. CA'!B19+'Comp. CA'!B21+'Comp. CA'!B22 -> 0.675 | K6: =+'Comp. CA'!C13+'Comp. CA'!C17+'Comp. CA'!C19+'Comp. CA'!C21+'Comp. CA'!C22 -> 0.376 | L6: =+'Comp. CA'!F21+'Comp. CA'!F22+'Comp. CA'!F23 -> 0.038 | M6: =+'Comp. CA'!G21+'Comp. CA'!G22+'Comp. CA'!G23 -> 0.052 | N6: ='Comp. CA'!J15+'Comp. CA'!J10 -> 0.092 | O6: ='Comp. CA'!K15+'Comp. CA'!K10 -> 0.085 | P6: ='Comp. CA'!N16+'Comp. CA'!N17 -> 0.089 | Q6: ='Comp. CA'!O16+'Comp. CA'!O17 -> 0.08 | R6: ='Comp. CA'!B35+'Comp. CA'!B29 -> 0.18 | S6: ='Comp. CA'!C35+'Comp. CA'!C29 -> 0.173 | T6: ='Comp. CA'!F29 -> 0.151 | U6: ='Comp. CA'!G29 -> 0.223 | V6: ='Comp. CA'!J29+'Comp. CA'!J30+'Comp. CA'!J31+'Comp. CA'!J32+'Comp. CA'!J33+'Comp. CA'!J37+'Comp. CA'!J38 -> 0.3561 | W6: ='Comp. CA'!K29+'Comp. CA'!K30+'Comp. CA'!K31+'Comp. CA'!K32+'Comp. CA'!K33+'Comp. CA'!K37+'Comp. CA'!K38 -> 0.288 | X6: 0 | Y6: 0 | Z6: ='Comp. CA'!B42+'Comp. CA'!B43+'Comp. CA'!B44+'Comp. CA'!B45+'Comp. CA'!B46+'Comp. CA'!B47+'Comp. CA'!B48+'Comp. CA'!B51+'Comp. CA'!B52 -> 1.219575 | AA6: ='Comp. CA'!C42+'Comp. CA'!C43+'Comp. CA'!C44+'Comp. CA'!C45+'Comp. CA'!C46+'Comp. CA'!C47+'Comp. CA'!C48+'Comp. CA'!C51+'Comp. CA'!C52 -> 0.9877 | AB6: =+'Comp. CA'!F37+'Comp. CA'!F38+'Comp. CA'!F39+'Comp. CA'!F40 -> 12.771 | AC6: =+'Comp. CA'!G37+'Comp. CA'!G38+'Comp. CA'!G39+'Comp. CA'!G40 -> 1.554 | AD6: 0 | AE6: 0 | AF6: ='Comp. CA'!J44+'Comp. CA'!J46+'Comp. CA'!J45 -> 0.0343 | AG6: ='Comp. CA'!K44+'Comp. CA'!K46+'Comp. CA'!K45 -> 0.029 | AH6: ='Comp. CA'!N45+'Comp. CA'!N51+'Comp. CA'!N52+'Comp. CA'!N49 -> 0.107 | AI6: ='Comp. CA'!O45+'Comp. CA'!O51+'Comp. CA'!O52+'Comp. CA'!O49 -> 0.475 | AJ6: =+'Comp. CA'!N39+'Comp. CA'!N38+'Comp. CA'!N40 -> 0.1142 | AK6: =+'Comp. CA'!O39+'Comp. CA'!O38+'Comp. CA'!O40 -> 0.777 | AL6: =SUM(B6,D6,F6,H6,J6,L6,N6,P6,R6,T6,V6,X6,Z6,AB6,AD6,AF6,AH6,AJ6) -> 21.741175 | AM6: =SUM(C6,E6,G6,I6,K6,M6,O6,Q6,S6,U6,W6,Y6,AA6,AC6,AE6,AG6,AI6,AK6) -> 9.7007 | AN6: =+AL6/$AL$9 -> 0.24187452 | AP6: =H6+AB6 -> 16.176 | AQ6: =AP6/AL6 -> 0.74402602 | AR6: =AP5+AP6 -> 28.587 | AS6: =AR6/(AL5+AL6) -> 0.70329611
A7: Commission de tenue de registre | B7: ='Comp. CA'!B6 -> 0.015 | C7: ='Comp. CA'!C6 -> 0.016 | D7: =+'Comp. CA'!F4 -> 0.155 | E7: =+'Comp. CA'!G4 -> 0.147 | F7: 0 | G7: 0 | H7: 0 | I7: 0 | J7: 0 | K7: 0 | L7: 0 | M7: 0 | N7: 0 | O7: 0 | P7: 0 | Q7: 0 | R7: ='Comp. CA'!B34 -> 0.066 | S7: ='Comp. CA'!C34 -> 0.075 | T7: 0 | U7: 0 | V7: =+'Comp. CA'!J36 -> 0.052 | W7: =+'Comp. CA'!K36 -> 0.045 | X7: ='Comp. CA'!N23 -> 0.022 | Y7: ='Comp. CA'!O23 -> 0.019 | Z7: ='Comp. CA'!B49 -> 0.072 | AA7: ='Comp. CA'!C49 -> 0.072 | AB7: =+'Comp. CA'!F42 -> 0.089 | AC7: =+'Comp. CA'!G42 -> 0.079 | AD7: 0 | AE7: 0 | AF7: ='Comp. CA'!J47 -> 0.015 | AG7: ='Comp. CA'!K47 -> 0.019 | AH7: 0 | AI7: 0 | AJ7: 0 | AK7: 0 | AL7: =SUM(B7,D7,F7,H7,J7,L7,N7,P7,R7,T7,V7,X7,Z7,AB7,AD7,AF7,AH7,AJ7) -> 0.486 | AM7: =SUM(C7,E7,G7,I7,K7,M7,O7,Q7,S7,U7,W7,Y7,AA7,AC7,AE7,AG7,AI7,AK7) -> 0.472 | AN7: =+AL7/$AL$9 -> 0.0054068381
A8: Commission sur étude et analyse | B8: ='Comp. CA'!B3+'Comp. CA'!B8 -> 0.503 | C8: ='Comp. CA'!C3+'Comp. CA'!C8 -> 0.634 | D8: =+'Comp. CA'!F5+'Comp. CA'!F10+'Comp. CA'!F11 -> 0.717 | E8: =+'Comp. CA'!G5+'Comp. CA'!G10+'Comp. CA'!G11 -> 8.167 | F8: 0 | G8: 0 | H8: =+'Comp. CA'!N3+'Comp. CA'!N6+'Comp. CA'!N8 -> 2.956 | I8: =+'Comp. CA'!O3+'Comp. CA'!O6+'Comp. CA'!O8 -> 5.706 | J8: ='Comp. CA'!B18 -> 0.068 | K8: ='Comp. CA'!C18 -> 0.047 | L8: =+'Comp. CA'!F16+'Comp. CA'!F17+'Comp. CA'!F18 -> 0.51 | M8: =+'Comp. CA'!G16+'Comp. CA'!G17+'Comp. CA'!G18 -> 0.799 | N8: ='Comp. CA'!J9+'Comp. CA'!J12 -> 0.497 | O8: ='Comp. CA'!K9+'Comp. CA'!K12 -> 0.434 | P8: ='Comp. CA'!N18 -> 0.002 | Q8: ='Comp. CA'!O18 -> 0.028 | R8: =+'Comp. CA'!B31+'Comp. CA'!B32+'Comp. CA'!B33 -> 0.428 | S8: =+'Comp. CA'!C31+'Comp. CA'!C32+'Comp. CA'!C33 -> 1.101 | T8: ='Comp. CA'!F27+'Comp. CA'!F32 -> 0.045 | U8: ='Comp. CA'!G27+'Comp. CA'!G32 -> 0.017 | V8: ='Comp. CA'!J34 -> 0 | W8: ='Comp. CA'!K34 -> 9.474 | X8: =+'Comp. CA'!N24+'Comp. CA'!N26+'Comp. CA'!N29+'Comp. CA'!N30+'Comp. CA'!N31 -> 0.59 | Y8: =+'Comp. CA'!O24+'Comp. CA'!O26+'Comp. CA'!O29+'Comp. CA'!O30+'Comp. CA'!O31 -> 0.16 | Z8: =+'Comp. CA'!B50+'Comp. CA'!B39 -> 0.006 | AA8: =+'Comp. CA'!C50+'Comp. CA'!C39 -> 3.639 | AB8: =+'Comp. CA'!F47+'Comp. CA'!F46+'Comp. CA'!F41 -> 1.724 | AC8: =+'Comp. CA'!G47+'Comp. CA'!G46+'Comp. CA'!G41 -> 6.785 | AD8: 0 | AE8: 0 | AF8: ='Comp. CA'!J49 -> 0.7 | AG8: ='Comp. CA'!K49 -> 0.7 | AH8: 0 | AI8: 0 | AJ8: ='Comp. CA'!N37 -> 0.578 | AK8: ='Comp. CA'!O37 -> 0.533 | AL8: =SUM(B8,D8,F8,H8,J8,L8,N8,P8,R8,T8,V8,X8,Z8,AB8,AD8,AF8,AH8,AJ8) -> 9.324 | AM8: =SUM(C8,E8,G8,I8,K8,M8,O8,Q8,S8,U8,W8,Y8,AA8,AC8,AE8,AG8,AI8,AK8) -> 38.224 | AN8: =+AL8/$AL$9 -> 0.10373119
A9: Total | B9: =SUM(B4:B8) -> 3.487 | C9: =SUM(C4:C8) -> 2.509 | D9: =SUM(D4:D8) -> 5.827 | E9: =SUM(E4:E8) -> 12.195 | F9: =SUM(F4:F8) -> 2.766 | G9: =SUM(G4:G8) -> 2.02 | H9: =SUM(H4:H8) -> 21.179 | I9: =SUM(I4:I8) -> 19.431 | ... AM9: =SUM(AM4:AM8) -> 90.7887 | AN9: =+AL9/$AL$9 -> 1
AB12: TVAL | AC12: MAC SA | AD12: BH INVEST
AB13: 6526000 | AC13: 5885000 | AD13: 210000
AB14: 3.1567122e+09 | AC14: 2.5721287e+09 | AD14: 1.1454756e+08
AB15: =+AB13/AB14 -> 0.0020673408 | AC15: =+AC13/AC14 -> 0.0022879881 | AD15: =+AD13/AD14 -> 0.0018332996
A18: Détail chiffre d'affaires (en MD) | B18: TOTAL
B19: 2025 | C19: 2024
A20: Commission de gestion OPCVM | B20: =AL4 -> 39.429 | C20: =AM4 -> 30.954 | D20: =B20/B$25 -> 0.43865478 | E20: =C20/C$25 -> 0.34094551
A21: Commission de courtage | B21: =AL5 -> 18.906 | C21: =AM5 -> 11.438 | D21: =B21/B$25 -> 0.21033268 | E21: =C21/C$25 -> 0.12598484
A22: Commission sur transaction boursière | B22: =AL6 -> 21.741175 | C22: =AM6 -> 9.7007 | D22: =B22/B$25 -> 0.24187452 | E22: =C22/C$25 -> 0.1068492
A23: Commission de tenue de registre | B23: =AL7 -> 0.486 | C23: =AM7 -> 0.472 | D23: =B23/B$25 -> 0.0054068381 | E23: =C23/C$25 -> 0.0051988849
A24: Commission sur étude et analyse | B24: =AL8 -> 9.324 | C24: =AM8 -> 38.224 | D24: =B24/B$25 -> 0.10373119 | E24: =C24/C$25 -> 0.42102156
A25: Total | B25: =AL9 -> 89.886175 | C25: =AM9 -> 90.7887

Sheet Autres analyses
A1: Détail chiffre d'affaires (en MD)
A4: Sociétés | B4: Commission de gestion OPCVM en MD | D4: Actifs Gérés | F4: Taux de commission moyen
B5: 2025 | C5: 2024 | D5: 2025 | E5: 2024 | F5: 2025 | G5: 2024
A6: MAC SA | B6: 9.013 | C6: 7.211 | D6: 1170 | E6: 1016 | F6: =+B6/D6 -> 0.0077034188 | G6: =+C6/E6 -> 0.0070974409
A7: TUNISIE VALEURS | B7: 8.292 | C7: 7.121 | D7: 2485 | E7: 1928 | F7: =+B7/D7 -> 0.0033368209 | G7: =+C7/E7 -> 0.0036934647
A8: AFC | B8: 3.897 | C8: 2.309 | D8: 422 | E8: 356 | F8: =+B8/D8 -> 0.0092345972 | G8: =+C8/E8 -> 0.0064859551
A9: UFI | B9: 3.896 | C9: 3.646 | D9: 47 | E9: 39 | F9: =+B9/D9 -> 0.082893617 | G9: =+C9/E9 -> 0.093487179
A10: BNA Capitaux | B10: 3.445 | C10: 2.731 | D10: 667 | E10: 540 | F10: =+B10/D10 -> 0.0051649175 | G10: =+C10/E10 -> 0.0050574074
A11: STB FINANCE | B11: 1.956 | C11: 1.612 | D11: 532 | E11: 400 | F11: =+B11/D11 -> 0.0036766917 | G11: =+C11/E11 -> 0.00403
A12: UNION CAPITAL | B12: 1.671 | C12: 1.025 | D12: 471 | E12: 293 | F12: =+B12/D12 -> 0.0035477707 | G12: =+C12/E12 -> 0.0034982935
A13: SBT | B13: 1.502 | C13: 1.036 | D13: 745 | E13: 789 | F13: =+B13/D13 -> 0.0020161074 | G13: =+C13/E13 -> 0.0013130545
A14: MAXULA | B14: 1.221 | C14: 1.053 | D14: 123 | E14: 125 | F14: =+B14/D14 -> 0.0099268293 | G14: =+C14/E14 -> 0.008424
A15: BH INVEST | B15: 1.217 | C15: 0.964 | D15: 379 | E15: 304 | F15: =+B15/D15 -> 0.0032110818 | G15: =+C15/E15 -> 0.0031710526
A16: AMEN INVEST | B16: 1.059 | C16: 0.783 | D16: 288 | E16: 239 | F16: =+B16/D16 -> 0.0036770833 | G16: =+C16/E16 -> 0.0032761506
A17: UIB FINANCE | B17: 0.898 | C17: 0.704 | D17: 223 | E17: 176 | F17: =+B17/D17 -> 0.0040269058 | G17: =+C17/E17 -> 0.004
... A22: BMCE | B22: 0.107 | C22: 0.1 | D22: 60 | E22: 38 | F22: =+B22/D22 -> 0.0017833333 | G22: =+C22/E22 -> 0.0026315789
A23: TOTAL | B23: =SUM(B6:B20) -> 38.974 | C23: =SUM(C6:C20) -> 30.588 | D23: =SUM(D6:D22) -> 7754 | E23: =SUM(E6:E22) -> 6319 | F23: =B23/D23 -> 0.005026309 | G23: =C23/E23 -> 0.0048406393
